Workbook

Sheet Executive Summary
B1: ="Financial Model:" & 'Data Sheet'!B1 -> Financial Model:TITAN COMPANY LTD
B3: Company Snapshot
B5: Parameter | C5: Details
B7: Company Name | C7: Titan Company Limited
B8: Ticker Symbol | C8: TITAN
B9: Sector / Industry | C9: Consumer Durables / Retail & Lifestyle
B10: Headquarters | C10: Bengaluru, Karnataka, India
B11: Founded Year | C11: 1984
B12: Managing Director & CEO | C12: Ajoy Chawla
B13: Listed Exchanges | C13: NSE & BSE
B14: Index Membership | C14: NIFTY 50, SENSEX, NIFTY Consumer Durables
B16: CORE PRODUCTS & KEY BRANDS
B18: Category | C18: Key Brands
B19: Jewelry | C19: Tanishq, CaratLane, Mia, Zoya
B20: Watches & Wearables | C20: Titan, Fastrack, Sonata, Helios, Xylys
B21: Eyewear | C21: Titan Eye+, Fastrack Eyewear
B22: Emerging Categories | C22: Skinn (Fragrances), Taneira (Sarees)
B23: Export / International Markets | C23: Middle East (UAE, Qatar), USA, Canada, Singapore
B25: VALUATION & MARKET DATA
B27: Current Market Price (CMP) | C27: 4516
B28: Market Capitalization (Cr) | C28: 400900
B29: Current Shares Outstanding (Cr) | C29: 88.77
B30: Base Historical Year | C30: FY26
B31: Projection Period | C31: FY27 - FY31

Sheet Assumptions and Drivers

Sheet Assumptions
B2: Assumption | C2: Value | D2: Source or reason
B3: Valuation date | C3: 46112 | D3: Date of the latest balance sheet
B4: Tax rate | C4: =WACC!G10 -> 0.2517 | D4: 22% base, 10% surcharge and 4% cess
B5: Risk-free rate | C5: =WACC!K23 -> 0.072 | D5: India 10-year government bond yield
B6: Market return | C6: =Rm!F7 -> 0.16449231 | D6: Average Nifty annual return 2000-2025 plus dividend yield (Rm sheet)
B7: Equity risk premium | C7: =WACC!K24 -> 0.092492308 | D7: Market return minus risk-free rate
B8: Beta | C8: =WACC!K25 -> 1.2 | D8: Median unlevered beta of peers, relevered at target debt/equity
B9: Cost of equity | C9: =WACC!K38 -> 0.18299077 | D9: Risk-free rate + beta x equity risk premium
B10: Pre-tax cost of debt | C10: =WACC!E23 -> 0.038535645 | D10: Interest expense divided by total debt
B11: Post-tax cost of debt | C11: =WACC!E25 -> 0.028836224 | D11: Pre-tax cost of debt x (1 - tax rate)
B12: Weight of equity | C12: =WACC!E33 -> 0.91509814 | D12: Target capital structure based on peer median
B13: Weight of debt | C13: =WACC!E32 -> 0.084901857 | D13: Target capital structure based on peer median
B14: WACC | C14: =WACC!K43 -> 0.16990276 | D14: Weighted average of cost of equity and post-tax cost of debt
B15: Expected growth, Mar-27 to Mar-31 | C15: =DCF!F18 -> 0.21061257 | D15: Median intrinsic growth rate over 4 years (reinvestment rate x ROIC)
B16: Reinvestment rate, forecast years | C16: 0.75 | D16: Share of NOPAT reinvested each year; expected growth divided by ROIC
B17: Terminal growth | C17: =DCF!D26 -> 0.0575 | D17: Long-run nominal growth of the Indian economy
B18: Terminal ROIC | C18: =DCF!D25 -> 0.16990276 | D18: Set equal to WACC
B19: Terminal reinvestment rate | C19: =C17/C18 -> 0.33842887 | D19: Terminal growth divided by terminal ROIC
B20: Discounting | C20: Mid-year convention | D20: Cash flows assumed to arrive evenly through each year
B21: Current market price (Rs) | C21: ='Data Sheet'!B8 -> 4515.7 | D21: Screener; 4/10/2026
B22: Shares outstanding (crore) | C22: ='Data Sheet'!B6 -> 88.778617 | D22: Screener
B23: Cash (Rs crore) | C23: =DCF!E35 -> 1917 | D23: Balance sheet, Mar-26
B24: Debt (Rs crore) | C24: =DCF!E36 -> 27448 | D24: Long-term and short-term borrowings, Mar-26
B25: Equity value per share (Rs) | C25: =DCF!E40 -> 350.66693 | D25: Model output

Sheet Historical_FS
B1: ="Financial Model:" & 'Data Sheet'!B1 -> Financial Model:TITAN COMPANY LTD
B2: Historical Financial Statements
B3: Year | C3: 42825 | D3: 43190 | E3: 43555 | F3: 43921 | G3: 44286 | H3: 44651 | I3: 45016 | J3: 45382 | K3: 45747 | L3: 46112
B5: #Income Statement
B7: Sales | C7: =IFERROR('Data Sheet'!B17,0) -> 13260.83 | D7: =IFERROR('Data Sheet'!C17,0) -> 16119.77 | E7: =IFERROR('Data Sheet'!D17,0) -> 19778.52 | F7: =IFERROR('Data Sheet'!E17,0) -> 21052 | G7: =IFERROR('Data Sheet'!F17,0) -> 21644 | H7: =IFERROR('Data Sheet'!G17,0) -> 28799 | I7: =IFERROR('Data Sheet'!H17,0) -> 40575 | J7: =IFERROR('Data Sheet'!I17,0) -> 51084 | ... L7: =IFERROR('Data Sheet'!K17,0) -> 87584
B8: Sales Growth % | C8: - | D8: =(D7/C7)-1 -> 0.21559284 | E8: =(E7/D7)-1 -> 0.22697284 | F8: =(F7/E7)-1 -> 0.064387022 | G8: =(G7/F7)-1 -> 0.028120844 | H8: =(H7/G7)-1 -> 0.3305766 | I8: =(I7/H7)-1 -> 0.40890309 | J8: =(J7/I7)-1 -> 0.25900185 | K8: =(K7/J7)-1 -> 0.18346253 | L8: =(L7/K7)-1 -> 0.44872304
B10: COGS | C10: =IFERROR(SUM('Data Sheet'!B18,'Data Sheet'!B20:B21)-'Data Sheet'!B19,0) -> 9711.69 | D10: =IFERROR(SUM('Data Sheet'!C18,'Data Sheet'!C20:C21)-'Data Sheet'!C19,0) -> 11856.37 | E10: =IFERROR(SUM('Data Sheet'!D18,'Data Sheet'!D20:D21)-'Data Sheet'!D19,0) -> 14636.04 | F10: =IFERROR(SUM('Data Sheet'!E18,'Data Sheet'!E20:E21)-'Data Sheet'!E19,0) -> 15422 | G10: =IFERROR(SUM('Data Sheet'!F18,'Data Sheet'!F20:F21)-'Data Sheet'!F19,0) -> 16592 | H10: =IFERROR(SUM('Data Sheet'!G18,'Data Sheet'!G20:G21)-'Data Sheet'!G19,0) -> 21869 | I10: =IFERROR(SUM('Data Sheet'!H18,'Data Sheet'!H20:H21)-'Data Sheet'!H19,0) -> 30639 | J10: =IFERROR(SUM('Data Sheet'!I18,'Data Sheet'!I20:I21)-'Data Sheet'!I19,0) -> 39789 | ... L10: =IFERROR(SUM('Data Sheet'!K18,'Data Sheet'!K20:K21)-'Data Sheet'!K19,0) -> 70769
B11: COGS % Sales | C11: =C10/C7 -> 0.73235914 | D11: =D10/D7 -> 0.73551732 | E11: =E10/E7 -> 0.73999672 | F11: =F10/F7 -> 0.73256698 | G11: =G10/G7 -> 0.76658658 | H11: =H10/H7 -> 0.75936664 | I11: =I10/I7 -> 0.75512015 | J11: =J10/J7 -> 0.77889359 | ... L11: =L10/L7 -> 0.80801288
B13: Gross Profit | C13: =C7-C10 -> 3549.14 | D13: =D7-D10 -> 4263.4 | E13: =E7-E10 -> 5142.48 | F13: =F7-F10 -> 5630 | G13: =G7-G10 -> 5052 | H13: =H7-H10 -> 6930 | I13: =I7-I10 -> 9936 | J13: =J7-J10 -> 11295 | ... L13: =L7-L10 -> 16815
B14: Gross Profit Margin | C14: =C13/C7 -> 0.26764086 | D14: =D13/D7 -> 0.26448268 | E14: =E13/E7 -> 0.26000328 | F14: =F13/F7 -> 0.26743302 | G14: =G13/G7 -> 0.23341342 | H14: =H13/H7 -> 0.24063336 | I14: =I13/I7 -> 0.24487985 | J14: =J13/J7 -> 0.22110641 | ... L14: =L13/L7 -> 0.19198712
B16: Selling & General Expenses | C16: =IFERROR(SUM('Data Sheet'!B22:B24),0) -> 2385.24 | D16: =IFERROR(SUM('Data Sheet'!C22:C24),0) -> 2619.2 | E16: =IFERROR(SUM('Data Sheet'!D22:D24),0) -> 3148.69 | F16: =IFERROR(SUM('Data Sheet'!E22:E24),0) -> 3167 | G16: =IFERROR(SUM('Data Sheet'!F22:F24),0) -> 3327 | H16: =IFERROR(SUM('Data Sheet'!G22:G24),0) -> 3586 | I16: =IFERROR(SUM('Data Sheet'!H22:H24),0) -> 5054 | J16: =IFERROR(SUM('Data Sheet'!I22:I24),0) -> 6003 | ... L16: =IFERROR(SUM('Data Sheet'!K22:K24),0) -> 8458
B17: S&G Exp % Sales | C17: =C16/C7 -> 0.17987109 | D17: =D16/D7 -> 0.16248371 | E17: =E16/E7 -> 0.15919745 | F17: =F16/F7 -> 0.15043701 | G17: =G16/G7 -> 0.15371466 | H17: =H16/H7 -> 0.12451821 | I17: =I16/I7 -> 0.12455946 | J17: =J16/J7 -> 0.11751233 | ... L17: =L16/L7 -> 0.09657015
B19: EBITDA | C19: =C13-C16 -> 1163.9 | D19: =D13-D16 -> 1644.2 | E19: =E13-E16 -> 1993.79 | F19: =F13-F16 -> 2463 | G19: =G13-G16 -> 1725 | H19: =H13-H16 -> 3344 | I19: =I13-I16 -> 4882 | J19: =J13-J16 -> 5292 | ... L19: =L13-L16 -> 8357
B20: EBITDA Margin | C20: =C19/C7 -> 0.08776977 | D20: =D19/D7 -> 0.10199897 | E20: =E19/E7 -> 0.10080582 | F20: =F19/F7 -> 0.11699601 | G20: =G19/G7 -> 0.079698762 | H20: =H19/H7 -> 0.11611514 | I20: =I19/I7 -> 0.12032039 | J20: =J19/J7 -> 0.10359408 | ... L20: =L19/L7 -> 0.095416971
B22: Interest | C22: =IFERROR('Data Sheet'!B27,0) -> 37.74 | D22: =IFERROR('Data Sheet'!C27,0) -> 52.92 | E22: =IFERROR('Data Sheet'!D27,0) -> 52.54 | F22: =IFERROR('Data Sheet'!E27,0) -> 166 | G22: =IFERROR('Data Sheet'!F27,0) -> 203 | H22: =IFERROR('Data Sheet'!G27,0) -> 218 | I22: =IFERROR('Data Sheet'!H27,0) -> 300 | J22: =IFERROR('Data Sheet'!I27,0) -> 619 | ... L22: =IFERROR('Data Sheet'!K27,0) -> 1180
B23: Interest % of Sales | C23: =C22/C7 -> 0.0028459757 | D23: =D22/D7 -> 0.0032829253 | E23: =E22/E7 -> 0.0026564172 | F23: =F22/F7 -> 0.0078852366 | G23: =G22/G7 -> 0.0093790427 | H23: =H22/H7 -> 0.0075697073 | I23: =I22/I7 -> 0.0073937153 | J23: =J22/J7 -> 0.012117297 | ... L23: =L22/L7 -> 0.01347278
B25: Depreciation | C25: =IFERROR('Data Sheet'!B26,0) -> 110.53 | D25: =IFERROR('Data Sheet'!C26,0) -> 131.43 | E25: =IFERROR('Data Sheet'!D26,0) -> 162.84 | F25: =IFERROR('Data Sheet'!E26,0) -> 348 | G25: =IFERROR('Data Sheet'!F26,0) -> 375 | H25: =IFERROR('Data Sheet'!G26,0) -> 399 | I25: =IFERROR('Data Sheet'!H26,0) -> 441 | J25: =IFERROR('Data Sheet'!I26,0) -> 584 | ... L25: =IFERROR('Data Sheet'!K26,0) -> 826
B26: Depreciation % of Sales | C26: =C25/C7 -> 0.008335074 | D26: =D25/D7 -> 0.0081533421 | E26: =E25/E7 -> 0.0082331742 | F26: =F25/F7 -> 0.016530496 | G26: =G25/G7 -> 0.017325818 | H26: =H25/H7 -> 0.013854648 | I26: =I25/I7 -> 0.010868762 | J26: =J25/J7 -> 0.011432151 | ... L26: =L25/L7 -> 0.0094309463
B28: Earnings Before Tax | C28: =C19+'Data Sheet'!B25-SUM(C22,C25) -> 973.25 | D28: =D19+'Data Sheet'!C25-SUM(D22,D25) -> 1529.78 | E28: =E19+'Data Sheet'!D25-SUM(E22,E25) -> 1956.89 | F28: =F19+'Data Sheet'!E25-SUM(F22,F25) -> 2102 | G28: =G19+'Data Sheet'!F25-SUM(G22,G25) -> 1327 | H28: =H19+'Data Sheet'!G25-SUM(H22,H25) -> 2904 | I28: =I19+'Data Sheet'!H25-SUM(I22,I25) -> 4447 | J28: =J19+'Data Sheet'!I25-SUM(J22,J25) -> 4623 | ... L28: =L19+'Data Sheet'!K25-SUM(L22,L25) -> 6801
B29: EBT % Sales | C29: =C28/C7 -> 0.073392842 | D29: =D28/D7 -> 0.094900858 | E29: =E28/E7 -> 0.098940163 | F29: =F28/F7 -> 0.099847995 | G29: =G28/G7 -> 0.061310294 | H29: =H28/H7 -> 0.10083683 | I29: =I28/I7 -> 0.10959951 | J29: =J28/J7 -> 0.090498003 | ... L29: =L28/L7 -> 0.077651169
B31: Tax | C31: =IFERROR('Data Sheet'!B29,0) -> 275.97 | D31: =IFERROR('Data Sheet'!C29,0) -> 427.87 | E31: =IFERROR('Data Sheet'!D29,0) -> 568.24 | F31: =IFERROR('Data Sheet'!E29,0) -> 609 | G31: =IFERROR('Data Sheet'!F29,0) -> 353 | H31: =IFERROR('Data Sheet'!G29,0) -> 706 | I31: =IFERROR('Data Sheet'!H29,0) -> 1173 | J31: =IFERROR('Data Sheet'!I29,0) -> 1127 | ... L31: =IFERROR('Data Sheet'!K29,0) -> 1728
B32: Effective Tax Rate | C32: =C31/C28 -> 0.2835551 | D32: =D31/D28 -> 0.27969381 | E32: =E31/E28 -> 0.29037912 | F32: =F31/F28 -> 0.28972407 | G32: =G31/G28 -> 0.26601356 | H32: =H31/H28 -> 0.24311295 | I32: =I31/I28 -> 0.26377333 | J32: =J31/J28 -> 0.24378109 | ... L32: =L31/L28 -> 0.25408028
B34: Net Profit | C34: =C28-C31 -> 697.28 | D34: =D28-D31 -> 1101.91 | E34: =E28-E31 -> 1388.65 | F34: =F28-F31 -> 1493 | G34: =G28-G31 -> 974 | H34: =H28-H31 -> 2198 | I34: =I28-I31 -> 3274 | J34: =J28-J31 -> 3496 | ... L34: =L28-L31 -> 5073
B35: Net Profit Margin | C35: =C34/C7 -> 0.052581927 | D35: =D34/D7 -> 0.068357675 | E35: =E34/E7 -> 0.070210006 | F35: =F34/F7 -> 0.070919628 | G35: =G34/G7 -> 0.045000924 | H35: =H34/H7 -> 0.076322095 | I35: =I34/I7 -> 0.08069008 | J35: =J34/J7 -> 0.068436301 | ... L35: =L34/L7 -> 0.057921538
B37: No of Equity Shares | C37: =IFERROR('Data Sheet'!B93,0) -> 88.78 | D37: =IFERROR('Data Sheet'!C93,0) -> 88.78 | E37: =IFERROR('Data Sheet'!D93,0) -> 88.78 | F37: =IFERROR('Data Sheet'!E93,0) -> 88.78 | G37: =IFERROR('Data Sheet'!F93,0) -> 88.78 | H37: =IFERROR('Data Sheet'!G93,0) -> 88.78 | I37: =IFERROR('Data Sheet'!H93,0) -> 88.78 | J37: =IFERROR('Data Sheet'!I93,0) -> 88.78 | ... L37: =IFERROR('Data Sheet'!K93,0) -> 88.78
B39: EPS | C39: =IFERROR(C34/C37,0) -> 7.8540212 | D39: =IFERROR(D34/D37,0) -> 12.411692 | E39: =IFERROR(E34/E37,0) -> 15.641473 | F39: =IFERROR(F34/F37,0) -> 16.816851 | G39: =IFERROR(G34/G37,0) -> 10.970939 | H39: =IFERROR(H34/H37,0) -> 24.757828 | I39: =IFERROR(I34/I37,0) -> 36.877675 | J39: =IFERROR(J34/J37,0) -> 39.378238 | ... L39: =IFERROR(L34/L37,0) -> 57.141248
B40: EPS growth % | C40: - | D40: =(D39/C39)-1 -> 0.58029773 | E40: =(E39/D39)-1 -> 0.26022089 | F40: =(F39/E39)-1 -> 0.075144925 | G40: =(G39/F39)-1 -> -0.34762224 | H40: =(H39/G39)-1 -> 1.2566735 | I40: =(I39/H39)-1 -> 0.48953594 | J40: =(J39/I39)-1 -> 0.067806964 | K40: =(K39/J39)-1 -> -0.045480549 | L40: =(L39/K39)-1 -> 0.52022775
B42: Dividend per Share | C42: =IFERROR('Data Sheet'!B31/Historical_FS!C37,0) -> 2.6000225 | D42: =IFERROR('Data Sheet'!C31/Historical_FS!D37,0) -> 3.7499437 | E42: =IFERROR('Data Sheet'!D31/Historical_FS!E37,0) -> 5 | F42: =IFERROR('Data Sheet'!E31/Historical_FS!F37,0) -> 4.0099121 | G42: =IFERROR('Data Sheet'!F31/Historical_FS!G37,0) -> 4.0099121 | H42: =IFERROR('Data Sheet'!G31/Historical_FS!H37,0) -> 7.5185853 | I42: =IFERROR('Data Sheet'!H31/Historical_FS!I37,0) -> 10.02478 | J42: =IFERROR('Data Sheet'!I31/Historical_FS!J37,0) -> 11.027258 | ... L42: =IFERROR('Data Sheet'!K31/Historical_FS!L37,0) -> 15.037171
B43: Dividend payout ratio | C43: =C42/C39 -> 0.33104348 | D43: =D42/D39 -> 0.30212994 | E43: =E42/E39 -> 0.31966298 | F43: =F42/F39 -> 0.23844608 | G43: =G42/G39 -> 0.36550308 | H43: =H42/H39 -> 0.30368517 | I43: =I42/I39 -> 0.27183873 | J43: =J42/J39 -> 0.28003432 | ... L43: =L42/L39 -> 0.26315789
B45: Retained Earnings | C45: =IFERROR(IF(C39>C42,1-C43,0),0) -> 0.66895652 | D45: =IFERROR(IF(D39>D42,1-D43,0),0) -> 0.69787006 | E45: =IFERROR(IF(E39>E42,1-E43,0),0) -> 0.68033702 | F45: =IFERROR(IF(F39>F42,1-F43,0),0) -> 0.76155392 | G45: =IFERROR(IF(G39>G42,1-G43,0),0) -> 0.63449692 | H45: =IFERROR(IF(H39>H42,1-H43,0),0) -> 0.69631483 | I45: =IFERROR(IF(I39>I42,1-I43,0),0) -> 0.72816127 | J45: =IFERROR(IF(J39>J42,1-J43,0),0) -> 0.71996568 | ... L45: =IFERROR(IF(L39>L42,1-L43,0),0) -> 0.73684211
B47: #Balance Sheet
B49: Equity Share Capital | C49: =IFERROR('Data Sheet'!B57,0) -> 88.78 | D49: =IFERROR('Data Sheet'!C57,0) -> 88.78 | E49: =IFERROR('Data Sheet'!D57,0) -> 88.78 | F49: =IFERROR('Data Sheet'!E57,0) -> 89 | G49: =IFERROR('Data Sheet'!F57,0) -> 89 | H49: =IFERROR('Data Sheet'!G57,0) -> 89 | I49: =IFERROR('Data Sheet'!H57,0) -> 89 | J49: =IFERROR('Data Sheet'!I57,0) -> 89 | ... L49: =IFERROR('Data Sheet'!K57,0) -> 89
B50: Reserves | C50: =IFERROR('Data Sheet'!B58,0) -> 4143.6 | D50: =IFERROR('Data Sheet'!C58,0) -> 5001.1 | E50: =IFERROR('Data Sheet'!D58,0) -> 5981.37 | F50: =IFERROR('Data Sheet'!E58,0) -> 6580 | G50: =IFERROR('Data Sheet'!F58,0) -> 7408 | H50: =IFERROR('Data Sheet'!G58,0) -> 9214 | I50: =IFERROR('Data Sheet'!H58,0) -> 11762 | J50: =IFERROR('Data Sheet'!I58,0) -> 9304 | ... L50: =IFERROR('Data Sheet'!K58,0) -> 15614
B51: Borrowings | C51: =IFERROR('Data Sheet'!B59,0) -> 1882.43 | D51: =IFERROR('Data Sheet'!C59,0) -> 1691.01 | E51: =IFERROR('Data Sheet'!D59,0) -> 2392.98 | F51: =IFERROR('Data Sheet'!E59,0) -> 3562 | G51: =IFERROR('Data Sheet'!F59,0) -> 5638 | H51: =IFERROR('Data Sheet'!G59,0) -> 7275 | I51: =IFERROR('Data Sheet'!H59,0) -> 9367 | J51: =IFERROR('Data Sheet'!I59,0) -> 15528 | ... L51: =IFERROR('Data Sheet'!K59,0) -> 30621
B52: Other Liabilities | C52: =IFERROR('Data Sheet'!B60,0) -> 2292.76 | D52: =IFERROR('Data Sheet'!C60,0) -> 2740.15 | E52: =IFERROR('Data Sheet'!D60,0) -> 3246.71 | F52: =IFERROR('Data Sheet'!E60,0) -> 3313 | G52: =IFERROR('Data Sheet'!F60,0) -> 3309 | H52: =IFERROR('Data Sheet'!G60,0) -> 4610 | I52: =IFERROR('Data Sheet'!H60,0) -> 5802 | J52: =IFERROR('Data Sheet'!I60,0) -> 6626 | ... L52: =IFERROR('Data Sheet'!K60,0) -> 14237
B53: Total Liabilities | C53: =IFERROR('Data Sheet'!B61,0) -> 8407.57 | D53: =IFERROR('Data Sheet'!C61,0) -> 9521.04 | E53: =IFERROR('Data Sheet'!D61,0) -> 11709.84 | F53: =IFERROR('Data Sheet'!E61,0) -> 13544 | G53: =IFERROR('Data Sheet'!F61,0) -> 16444 | H53: =IFERROR('Data Sheet'!G61,0) -> 21188 | I53: =IFERROR('Data Sheet'!H61,0) -> 27020 | J53: =IFERROR('Data Sheet'!I61,0) -> 31547 | ... L53: =IFERROR('Data Sheet'!K61,0) -> 60561
B55: Fixed Asset Net Block | C55: =IFERROR('Data Sheet'!B62,0) -> 1188.72 | D55: =IFERROR('Data Sheet'!C62,0) -> 1473.81 | E55: =IFERROR('Data Sheet'!D62,0) -> 1566.63 | F55: =IFERROR('Data Sheet'!E62,0) -> 2633 | G55: =IFERROR('Data Sheet'!F62,0) -> 2523 | H55: =IFERROR('Data Sheet'!G62,0) -> 2544 | I55: =IFERROR('Data Sheet'!H62,0) -> 2998 | J55: =IFERROR('Data Sheet'!I62,0) -> 3709 | ... L55: =IFERROR('Data Sheet'!K62,0) -> 6878
B56: Capital Work in Progress | C56: =IFERROR('Data Sheet'!B63,0) -> 152.07 | D56: =IFERROR('Data Sheet'!C63,0) -> 43.37 | E56: =IFERROR('Data Sheet'!D63,0) -> 31.77 | F56: =IFERROR('Data Sheet'!E63,0) -> 18 | G56: =IFERROR('Data Sheet'!F63,0) -> 32 | H56: =IFERROR('Data Sheet'!G63,0) -> 85 | I56: =IFERROR('Data Sheet'!H63,0) -> 144 | J56: =IFERROR('Data Sheet'!I63,0) -> 97 | ... L56: =IFERROR('Data Sheet'!K63,0) -> 163
B57: Investments | C57: =IFERROR('Data Sheet'!B64,0) -> 430.73 | D57: =IFERROR('Data Sheet'!C64,0) -> 35.99 | E57: =IFERROR('Data Sheet'!D64,0) -> 108.42 | F57: =IFERROR('Data Sheet'!E64,0) -> 158 | G57: =IFERROR('Data Sheet'!F64,0) -> 2824 | H57: =IFERROR('Data Sheet'!G64,0) -> 294 | I57: =IFERROR('Data Sheet'!H64,0) -> 2515 | J57: =IFERROR('Data Sheet'!I64,0) -> 2345 | ... L57: =IFERROR('Data Sheet'!K64,0) -> 3506
B58: Other Assets | C58: =IFERROR('Data Sheet'!B65-SUM('Data Sheet'!B67:B69),0) -> 723.78 | D58: =IFERROR('Data Sheet'!C65-SUM('Data Sheet'!C67:C69),0) -> 1129.43 | E58: =IFERROR('Data Sheet'!D65-SUM('Data Sheet'!D67:D69),0) -> 1477.27 | F58: =IFERROR('Data Sheet'!E65-SUM('Data Sheet'!E67:E69),0) -> 1939 | G58: =IFERROR('Data Sheet'!F65-SUM('Data Sheet'!F67:F69),0) -> 1731 | H58: =IFERROR('Data Sheet'!G65-SUM('Data Sheet'!G67:G69),0) -> 2518 | I58: =IFERROR('Data Sheet'!H65-SUM('Data Sheet'!H67:H69),0) -> 2762 | J58: =IFERROR('Data Sheet'!I65-SUM('Data Sheet'!I67:I69),0) -> 3801 | ... L58: =IFERROR('Data Sheet'!K65-SUM('Data Sheet'!K67:K69),0) -> 4438
...

Sheet Supporting Schedules

Sheet Du Pont Analysis
B3: ='Data Sheet'!B1 -> TITAN COMPANY LTD
B4: TITAN I BSE:500114
B5: =CONCATENATE(" ","INR "&'Data Sheet'!B8) -> INR 4515.7
B6: 52 week (High- 5187 & Low- 3500)
B8: About The Company
B9: Titan Company Ltd is among India’s most respected lifestyle companies. It has established leadership positions in the Watches, Jewellery and Eyewear categories led by its trusted brands and differentiated customer experience. It was founded in 1984 as a joint-venture between TATA Group and Tamilnadu Industrial Development Corporation (TIDCO).
B11: Financial Summary
B36: Dupont Analysis- Return on Equity & Return on Asset
B38: Return on Equity
C39: =Historical_FS!F3 -> 43921 | D39: =Historical_FS!G3 -> 44286 | E39: =Historical_FS!H3 -> 44651 | F39: =Historical_FS!I3 -> 45016 | G39: =Historical_FS!J3 -> 45382 | H39: =Historical_FS!K3 -> 45747 | I39: =Historical_FS!L3 -> 46112
B40: Net Profit | C40: ='Data Sheet'!E30 -> 1501 | D40: ='Data Sheet'!F30 -> 973 | E40: ='Data Sheet'!G30 -> 2173 | F40: ='Data Sheet'!H30 -> 3250 | G40: ='Data Sheet'!I30 -> 3496 | H40: ='Data Sheet'!J30 -> 3337 | I40: ='Data Sheet'!K30 -> 5073
B41: Average Shareholder Equity | C41: =(('Data Sheet'!E57+'Data Sheet'!E58)+('Data Sheet'!D57+'Data Sheet'!D58))/2 -> 6369.575 | D41: =(('Data Sheet'!F57+'Data Sheet'!F58)+('Data Sheet'!E57+'Data Sheet'!E58))/2 -> 7083 | E41: =(('Data Sheet'!G57+'Data Sheet'!G58)+('Data Sheet'!F57+'Data Sheet'!F58))/2 -> 8400 | F41: =(('Data Sheet'!H57+'Data Sheet'!H58)+('Data Sheet'!G57+'Data Sheet'!G58))/2 -> 10577 | G41: =(('Data Sheet'!I57+'Data Sheet'!I58)+('Data Sheet'!H57+'Data Sheet'!H58))/2 -> 10622 | H41: =(('Data Sheet'!J57+'Data Sheet'!J58)+('Data Sheet'!I57+'Data Sheet'!I58))/2 -> 10508.5 | I41: =(('Data Sheet'!K57+'Data Sheet'!K58)+('Data Sheet'!J57+'Data Sheet'!J58))/2 -> 13663.5
B42: Return on Equity | C42: =C40/C41 -> 0.23565152 | D42: =D40/D41 -> 0.13737117 | E42: =E40/E41 -> 0.25869048 | F42: =F40/F41 -> 0.30727049 | G42: =G40/G41 -> 0.32912822 | H42: =H40/H41 -> 0.31755246 | I42: =I40/I41 -> 0.37128115
B44: ROE- DuPont Equation
C45: =C39 -> 43921 | D45: =D39 -> 44286 | E45: =E39 -> 44651 | F45: =F39 -> 45016 | G45: =G39 -> 45382 | H45: =H39 -> 45747 | I45: =I39 -> 46112
B46: Net Profit | C46: =C40 -> 1501 | D46: =D40 -> 973 | E46: =E40 -> 2173 | F46: =F40 -> 3250 | G46: =G40 -> 3496 | H46: =H40 -> 3337 | I46: =I40 -> 5073
B47: Revenue | C47: ='Data Sheet'!E17 -> 21052 | D47: ='Data Sheet'!F17 -> 21644 | E47: ='Data Sheet'!G17 -> 28799 | F47: ='Data Sheet'!H17 -> 40575 | G47: ='Data Sheet'!I17 -> 51084 | H47: ='Data Sheet'!J17 -> 60456 | I47: ='Data Sheet'!K17 -> 87584
B48: Net Profit Margin (A) | C48: =C46/C47 -> 0.071299639 | D48: =D46/D47 -> 0.044954722 | E48: =E46/E47 -> 0.075454009 | F48: =F46/F47 -> 0.080098583 | G48: =G46/G47 -> 0.068436301 | H48: =H46/H47 -> 0.055197168 | I48: =I46/I47 -> 0.057921538
B50: Revenue | C50: =C47 -> 21052 | D50: =D47 -> 21644 | E50: =E47 -> 28799 | F50: =F47 -> 40575 | G50: =G47 -> 51084 | H50: =H47 -> 60456 | I50: =I47 -> 87584
B51: Average Total Assets | C51: =('Data Sheet'!E66+'Data Sheet'!D66)/2 -> 12626.92 | D51: =('Data Sheet'!F66+'Data Sheet'!E66)/2 -> 14994 | E51: =('Data Sheet'!G66+'Data Sheet'!F66)/2 -> 18816 | F51: =('Data Sheet'!H66+'Data Sheet'!G66)/2 -> 24104 | G51: =('Data Sheet'!I66+'Data Sheet'!H66)/2 -> 29283.5 | H51: =('Data Sheet'!J66+'Data Sheet'!I66)/2 -> 36096 | I51: =('Data Sheet'!K66+'Data Sheet'!J66)/2 -> 50603
B52: Asset Turnover Ratio (B) | C52: =C50/C51 -> 1.6672316 | D52: =D50/D51 -> 1.4435107 | E52: =E50/E51 -> 1.5305591 | F52: =F50/F51 -> 1.6833306 | G52: =G50/G51 -> 1.7444636 | H52: =H50/H51 -> 1.674867 | I52: =I50/I51 -> 1.7308065
B54: =B51 -> Average Total Assets | C54: =C51 -> 12626.92 | D54: =D51 -> 14994 | E54: =E51 -> 18816 | F54: =F51 -> 24104 | G54: =G51 -> 29283.5 | H54: =H51 -> 36096 | I54: =I51 -> 50603
B55: =B41 -> Average Shareholder Equity | C55: =C41 -> 6369.575 | D55: =D41 -> 7083 | E55: =E41 -> 8400 | F55: =F41 -> 10577 | G55: =G41 -> 10622 | H55: =H41 -> 10508.5 | I55: =I41 -> 13663.5
B56: Financial Leverage (C) | C56: =C54/C55 -> 1.9823803 | D56: =D54/D55 -> 2.1168996 | E56: =E54/E55 -> 2.24 | F56: =F54/F55 -> 2.2789071 | G56: =G54/G55 -> 2.7568725 | H56: =H54/H55 -> 3.4349336 | I56: =I54/I55 -> 3.7035167
B58: Return on Equity (A*B*C) | C58: =C48*C52*C56 -> 0.23565152 | D58: =D48*D52*D56 -> 0.13737117 | E58: =E48*E52*E56 -> 0.25869048 | F58: =F48*F52*F56 -> 0.30727049 | G58: =G48*G52*G56 -> 0.32912822 | H58: =H48*H52*H56 -> 0.31755246 | I58: =I48*I52*I56 -> 0.37128115
B60: Return on Asset
C61: =C39 -> 43921 | D61: =D39 -> 44286 | E61: =E39 -> 44651 | F61: =F39 -> 45016 | G61: =G39 -> 45382 | H61: =H39 -> 45747 | I61: =I39 -> 46112
B62: Net Profit | C62: =C46 -> 1501 | D62: =D46 -> 973 | E62: =E46 -> 2173 | F62: =F46 -> 3250 | G62: =G46 -> 3496 | H62: =H46 -> 3337 | I62: =I46 -> 5073
B63: Average Total Asset | C63: =C54 -> 12626.92 | D63: =D54 -> 14994 | E63: =E54 -> 18816 | F63: =F54 -> 24104 | G63: =G54 -> 29283.5 | H63: =H54 -> 36096 | I63: =I54 -> 50603
B64: Return on Asset | C64: =C62/C63 -> 0.11887301 | D64: =D62/D63 -> 0.064892624 | E64: =E62/E63 -> 0.11548682 | F64: =F62/F63 -> 0.13483239 | G64: =G62/G63 -> 0.11938464 | H64: =H62/H63 -> 0.092447917 | I64: =I62/I63 -> 0.10025097
B66: ROA- DuPont Equation
C67: =C45 -> 43921 | D67: =D45 -> 44286 | E67: =E45 -> 44651 | F67: =F45 -> 45016 | G67: =G45 -> 45382 | H67: =H45 -> 45747 | I67: =I45 -> 46112
B68: Net Profit | C68: =C46 -> 1501 | D68: =D46 -> 973 | E68: =E46 -> 2173 | F68: =F46 -> 3250 | G68: =G46 -> 3496 | H68: =H46 -> 3337 | I68: =I46 -> 5073
B69: Revenue | C69: =C50 -> 21052 | D69: =D50 -> 21644 | E69: =E50 -> 28799 | F69: =F50 -> 40575 | G69: =G50 -> 51084 | H69: =H50 -> 60456 | I69: =I50 -> 87584
B70: =B48 -> Net Profit Margin (A) | C70: =C68/C69 -> 0.071299639 | D70: =D68/D69 -> 0.044954722 | E70: =E68/E69 -> 0.075454009 | F70: =F68/F69 -> 0.080098583 | G70: =G68/G69 -> 0.068436301 | H70: =H68/H69 -> 0.055197168 | I70: =I68/I69 -> 0.057921538
B72: Revenue | C72: =C50 -> 21052 | D72: =D50 -> 21644 | E72: =E50 -> 28799 | F72: =F50 -> 40575 | G72: =G50 -> 51084 | H72: =H50 -> 60456 | I72: =I50 -> 87584
B73: Average Total Assets | C73: =C63 -> 12626.92 | D73: =D63 -> 14994 | E73: =E63 -> 18816 | F73: =F63 -> 24104 | G73: =G63 -> 29283.5 | H73: =H63 -> 36096 | I73: =I63 -> 50603
B74: Asset Turnover Ratio (B) | C74: =C72/C73 -> 1.6672316 | D74: =D72/D73 -> 1.4435107 | E74: =E72/E73 -> 1.5305591 | F74: =F72/F73 -> 1.6833306 | G74: =G72/G73 -> 1.7444636 | H74: =H72/H73 -> 1.674867 | I74: =I72/I73 -> 1.7308065
B76: Return on Asset (A*B) | C76: =C70*C74 -> 0.11887301 | D76: =D70*D74 -> 0.064892624 | E76: =E70*E74 -> 0.11548682 | F76: =F70*F74 -> 0.13483239 | G76: =G70*G74 -> 0.11938464 | H76: =H70*H74 -> 0.092447917 | I76: =I70*I74 -> 0.10025097
B93: Disclamer: this project is only for educational purpose

Sheet Altman Z score
B3: ='Data Sheet'!B1 -> TITAN COMPANY LTD
B4: TITAN I BSE:500114
B5: =CONCATENATE(" ","INR "&'Data Sheet'!B8) -> INR 4515.7
B6: 52 week (High- 5187 & Low- 3500)
B9: Financial Summary
B33: Altman Z score Analysis Calculation
B35: 1. Working Capital/ Total Assets
C36: =Historical_FS!F3 -> 43921 | D36: =Historical_FS!G3 -> 44286 | E36: =Historical_FS!H3 -> 44651 | F36: =Historical_FS!I3 -> 45016 | G36: =Historical_FS!J3 -> 45382 | H36: =Historical_FS!K3 -> 45747 | I36: =Historical_FS!L3 -> 46112
B37: Working Capital | C37: ='Data Sheet'!E65-'Data Sheet'!E60 -> 7422 | D37: ='Data Sheet'!F65-'Data Sheet'!F60 -> 7756 | E37: ='Data Sheet'!G65-'Data Sheet'!G60 -> 13655 | F37: ='Data Sheet'!H65-'Data Sheet'!H60 -> 15561 | G37: ='Data Sheet'!I65-'Data Sheet'!I60 -> 18770 | H37: ='Data Sheet'!J65-'Data Sheet'!J60 -> 26246 | I37: ='Data Sheet'!K65-'Data Sheet'!K60 -> 35777
B38: Total Assets | C38: ='Data Sheet'!E66 -> 13544 | D38: ='Data Sheet'!F66 -> 16444 | E38: ='Data Sheet'!G66 -> 21188 | F38: ='Data Sheet'!H66 -> 27020 | G38: ='Data Sheet'!I66 -> 31547 | H38: ='Data Sheet'!J66 -> 40645 | I38: ='Data Sheet'!K66 -> 60561
B39: Working Capital/ Total Assets (A) | C39: =C37/C38 -> 0.54799173 | D39: =D37/D38 -> 0.4716614 | E39: =E37/E38 -> 0.64446857 | F39: =F37/F38 -> 0.57590674 | G39: =G37/G38 -> 0.59498526 | H39: =H37/H38 -> 0.64573748 | I39: =I37/I38 -> 0.59075973
B41: 2. Retained Earnings/ Total Assets
C42: =C36 -> 43921 | D42: =D36 -> 44286 | E42: =E36 -> 44651 | F42: =F36 -> 45016 | G42: =G36 -> 45382 | H42: =H36 -> 45747 | I42: =I36 -> 46112
B43: Retained Earnings | C43: ='Data Sheet'!E58 -> 6580 | D43: ='Data Sheet'!F58 -> 7408 | E43: ='Data Sheet'!G58 -> 9214 | F43: ='Data Sheet'!H58 -> 11762 | G43: ='Data Sheet'!I58 -> 9304 | H43: ='Data Sheet'!J58 -> 11535 | I43: ='Data Sheet'!K58 -> 15614
B44: Total Assets | C44: =C38 -> 13544 | D44: =D38 -> 16444 | E44: =E38 -> 21188 | F44: =F38 -> 27020 | G44: =G38 -> 31547 | H44: =H38 -> 40645 | I44: =I38 -> 60561
B45: Retained Earnings/ Total Assets (B) | C45: =C43/C44 -> 0.48582398 | D45: =D43/D44 -> 0.45049866 | E45: =E43/E44 -> 0.43486879 | F45: =F43/F44 -> 0.43530718 | G45: =G43/G44 -> 0.29492503 | H45: =H43/H44 -> 0.28379875 | I45: =I43/I44 -> 0.25782269
B47: 3. EBIT/ Total Assets
C48: =C42 -> 43921 | D48: =D42 -> 44286 | E48: =E42 -> 44651 | F48: =F42 -> 45016 | G48: =G42 -> 45382 | H48: =H42 -> 45747 | I48: =I42 -> 46112
B49: EBIT | C49: =Historical_FS!F28+Historical_FS!F22 -> 2268 | D49: =Historical_FS!G28+Historical_FS!G22 -> 1530 | E49: =Historical_FS!H28+Historical_FS!H22 -> 3122 | F49: =Historical_FS!I28+Historical_FS!I22 -> 4747 | G49: =Historical_FS!J28+Historical_FS!J22 -> 5242 | H49: =Historical_FS!K28+Historical_FS!K22 -> 5488 | I49: =Historical_FS!L28+Historical_FS!L22 -> 7981
B50: Total Assets | C50: =C44 -> 13544 | D50: =D44 -> 16444 | E50: =E44 -> 21188 | F50: =F44 -> 27020 | G50: =G44 -> 31547 | H50: =H44 -> 40645 | I50: =I44 -> 60561
B51: EBIT/ Total Assets (C) | C51: =C49/C50 -> 0.16745422 | D51: =D49/D50 -> 0.093043055 | E51: =E49/E50 -> 0.14734756 | F51: =F49/F50 -> 0.17568468 | G51: =G49/G50 -> 0.16616477 | H51: =H49/H50 -> 0.13502276 | I51: =I49/I50 -> 0.13178448
B53: 4. Market Cap/ Long Term Liability
C54: =C48 -> 43921 | D54: =D48 -> 44286 | E54: =E48 -> 44651 | F54: =F48 -> 45016 | G54: =G48 -> 45382 | H54: =H48 -> 45747 | I54: =I48 -> 46112
B55: Market Cap | C55: ='Data Sheet'!E90*'Data Sheet'!E93 -> 82893.886 | D55: ='Data Sheet'!F90*'Data Sheet'!F93 -> 138323.68 | E55: ='Data Sheet'!G90*'Data Sheet'!G93 -> 225159.4 | F55: ='Data Sheet'!H90*'Data Sheet'!H93 -> 223272.82 | G55: ='Data Sheet'!I90*'Data Sheet'!I93 -> 337523.8 | H55: ='Data Sheet'!J90*'Data Sheet'!J93 -> 271964.21 | I55: ='Data Sheet'!K90*'Data Sheet'!K93 -> 350805.29
B56: Long Term Liability | C56: ='Data Sheet'!E59 -> 3562 | D56: ='Data Sheet'!F59 -> 5638 | E56: ='Data Sheet'!G59 -> 7275 | F56: ='Data Sheet'!H59 -> 9367 | G56: ='Data Sheet'!I59 -> 15528 | H56: ='Data Sheet'!J59 -> 20777 | I56: ='Data Sheet'!K59 -> 30621
B57: Market Cap/ Long Term Liability (D) | C57: =C55/C56 -> 23.271725 | D57: =D55/D56 -> 24.534175 | E57: =E55/E56 -> 30.949745 | F57: =F55/F56 -> 23.836108 | G57: =G55/G56 -> 21.736463 | H57: =H55/H56 -> 13.089677 | I57: =I55/I56 -> 11.456363
B59: 5. Sales/ Total Assets
C60: =C36 -> 43921 | D60: =D36 -> 44286 | E60: =E36 -> 44651 | F60: =F36 -> 45016 | G60: =G36 -> 45382 | H60: =H36 -> 45747 | I60: =I36 -> 46112
B61: Sales | C61: ='Data Sheet'!E17 -> 21052 | D61: ='Data Sheet'!F17 -> 21644 | E61: ='Data Sheet'!G17 -> 28799 | F61: ='Data Sheet'!H17 -> 40575 | G61: ='Data Sheet'!I17 -> 51084 | H61: ='Data Sheet'!J17 -> 60456 | I61: ='Data Sheet'!K17 -> 87584
B62: Total Assets | C62: =C44 -> 13544 | D62: =D44 -> 16444 | E62: =E44 -> 21188 | F62: =F44 -> 27020 | G62: =G44 -> 31547 | H62: =H44 -> 40645 | I62: =I44 -> 60561
B63: Sales/ Total Assets (E) | C63: =C61/C62 -> 1.5543414 | D63: =D61/D62 -> 1.3162248 | E63: =E61/E62 -> 1.3592128 | F63: =F61/F62 -> 1.5016654 | G63: =G61/G62 -> 1.6192982 | H63: =H61/H62 -> 1.4874154 | I63: =I61/I62 -> 1.4462113
B65: Atlman Z Score
C66: =C42 -> 43921 | D66: =D42 -> 44286 | E66: =E42 -> 44651 | F66: =F42 -> 45016 | G66: =G42 -> 45382 | H66: =H42 -> 45747 | I66: =I42 -> 46112
B67: Final Score | C67: =(C39*1.2)+(C45*1.4)+(C51*3.3)+(C57*0.6)+(C63*1) -> 17.407719 | D67: =(D39*1.2)+(D45*1.4)+(D51*3.3)+(D57*0.6)+(D63*1) -> 17.540464 | E67: =(E39*1.2)+(E45*1.4)+(E51*3.3)+(E57*0.6)+(E63*1) -> 21.797485 | F67: =(F39*1.2)+(F45*1.4)+(F51*3.3)+(F57*0.6)+(F63*1) -> 17.683608 | G67: =(G39*1.2)+(G45*1.4)+(G51*3.3)+(G57*0.6)+(G63*1) -> 16.336397 | H67: =(H39*1.2)+(H45*1.4)+(H51*3.3)+(H57*0.6)+(H63*1) -> 10.959 | I67: =(I39*1.2)+(I45*1.4)+(I51*3.3)+(I57*0.6)+(I63*1) -> 9.8247813
B68: Financial Stability | C68: =IF(C67<1.8, "Distressed",IF(C67>3,"Strong","Grey Zone")) -> Strong | D68: =IF(D67<1.8, "Distressed",IF(D67>3,"Strong","Grey Zone")) -> Strong | E68: =IF(E67<1.8, "Distressed",IF(E67>3,"Strong","Grey Zone")) -> Strong | F68: =IF(F67<1.8, "Distressed",IF(F67>3,"Strong","Grey Zone")) -> Strong | G68: =IF(G67<1.8, "Distressed",IF(G67>3,"Strong","Grey Zone")) -> Strong | H68: =IF(H67<1.8, "Distressed",IF(H67>3,"Strong","Grey Zone")) -> Strong | I68: =IF(I67<1.8, "Distressed",IF(I67>3,"Strong","Grey Zone")) -> Strong
B70: Disclamer: this project is only for educational purpose

Sheet Financials>
B1: ="Ratio Analysis: " & 'Data Sheet'!B1 -> Ratio Analysis: TITAN COMPANY LTD
B2: Historical Financial Statements
B3: Particulars | C3: 42825 | D3: 43190 | E3: 43555 | F3: 43921 | G3: 44286 | H3: 44651 | I3: 45016 | J3: 45382 | K3: 45747 | L3: 46112 | M3: Trend | N3: Mean | O3: Median
B5: Sales Growth | C5: =IFERROR(Historical_FS!C8,0) -> - | D5: =IFERROR(Historical_FS!D8,0) -> 0.21559284 | E5: =IFERROR(Historical_FS!E8,0) -> 0.22697284 | F5: =IFERROR(Historical_FS!F8,0) -> 0.064387022 | G5: =IFERROR(Historical_FS!G8,0) -> 0.028120844 | H5: =IFERROR(Historical_FS!H8,0) -> 0.3305766 | I5: =IFERROR(Historical_FS!I8,0) -> 0.40890309 | J5: =IFERROR(Historical_FS!J8,0) -> 0.25900185 | ... L5: =IFERROR(Historical_FS!L8,0) -> 0.44872304 | N5: =AVERAGE(D5:L5) -> 0.24063785 | O5: =MEDIAN(D5:L5) -> 0.22697284
B6: EBITDA Growth | C6: - | D6: =IFERROR(Historical_FS!D19/Historical_FS!C19-1,0) -> 0.41266432 | E6: =IFERROR(Historical_FS!E19/Historical_FS!D19-1,0) -> 0.21262012 | F6: =IFERROR(Historical_FS!F19/Historical_FS!E19-1,0) -> 0.23533572 | G6: =IFERROR(Historical_FS!G19/Historical_FS!F19-1,0) -> -0.29963459 | H6: =IFERROR(Historical_FS!H19/Historical_FS!G19-1,0) -> 0.93855072 | I6: =IFERROR(Historical_FS!I19/Historical_FS!H19-1,0) -> 0.45992823 | J6: =IFERROR(Historical_FS!J19/Historical_FS!I19-1,0) -> 0.083981975 | K6: =IFERROR(Historical_FS!K19/Historical_FS!J19-1,0) -> 0.075963719 | L6: =IFERROR(Historical_FS!L19/Historical_FS!K19-1,0) -> 0.46768528 | N6: =AVERAGE(D6:L6) -> 0.28745505 | O6: =MEDIAN(D6:L6) -> 0.23533572
B7: EBT Growth | C7: - | D7: =IFERROR(Historical_FS!D28/Historical_FS!C28-1,0) -> 0.57182635 | E7: =IFERROR(Historical_FS!E28/Historical_FS!D28-1,0) -> 0.27919701 | F7: =IFERROR(Historical_FS!F28/Historical_FS!E28-1,0) -> 0.074153376 | G7: =IFERROR(Historical_FS!G28/Historical_FS!F28-1,0) -> -0.36869648 | H7: =IFERROR(Historical_FS!H28/Historical_FS!G28-1,0) -> 1.1883949 | I7: =IFERROR(Historical_FS!I28/Historical_FS!H28-1,0) -> 0.53133609 | J7: =IFERROR(Historical_FS!J28/Historical_FS!I28-1,0) -> 0.039577243 | K7: =IFERROR(Historical_FS!K28/Historical_FS!J28-1,0) -> -0.019035258 | L7: =IFERROR(Historical_FS!L28/Historical_FS!K28-1,0) -> 0.49966924 | N7: =AVERAGE(D7:L7) -> 0.31071361 | O7: =MEDIAN(D7:L7) -> 0.27919701
B8: Net Profit Growth | C8: - | D8: =IFERROR(Historical_FS!D34/Historical_FS!C34-1,0) -> 0.58029773 | E8: =IFERROR(Historical_FS!E34/Historical_FS!D34-1,0) -> 0.26022089 | F8: =IFERROR(Historical_FS!F34/Historical_FS!E34-1,0) -> 0.075144925 | G8: =IFERROR(Historical_FS!G34/Historical_FS!F34-1,0) -> -0.34762224 | H8: =IFERROR(Historical_FS!H34/Historical_FS!G34-1,0) -> 1.2566735 | I8: =IFERROR(Historical_FS!I34/Historical_FS!H34-1,0) -> 0.48953594 | J8: =IFERROR(Historical_FS!J34/Historical_FS!I34-1,0) -> 0.067806964 | K8: =IFERROR(Historical_FS!K34/Historical_FS!J34-1,0) -> -0.045480549 | L8: =IFERROR(Historical_FS!L34/Historical_FS!K34-1,0) -> 0.52022775 | N8: =AVERAGE(D8:L8) -> 0.31742277 | O8: =MEDIAN(D8:L8) -> 0.26022089
B9: Dividend Growth | C9: - | D9: =IFERROR(Historical_FS!D42/Historical_FS!C42-1,0) -> 0.44227353 | E9: =IFERROR(Historical_FS!E42/Historical_FS!D42-1,0) -> 0.33335336 | F9: =IFERROR(Historical_FS!F42/Historical_FS!E42-1,0) -> -0.19801757 | G9: =IFERROR(Historical_FS!G42/Historical_FS!F42-1,0) -> 0 | H9: =IFERROR(Historical_FS!H42/Historical_FS!G42-1,0) -> 0.875 | I9: =IFERROR(Historical_FS!I42/Historical_FS!H42-1,0) -> 0.33333333 | J9: =IFERROR(Historical_FS!J42/Historical_FS!I42-1,0) -> 0.1 | K9: =IFERROR(Historical_FS!K42/Historical_FS!J42-1,0) -> 0 | L9: =IFERROR(Historical_FS!L42/Historical_FS!K42-1,0) -> 0.36363636 | N9: =AVERAGE(D9:L9) -> 0.24995322 | O9: =MEDIAN(D9:L9) -> 0.33333333
B11: Gross Margin | C11: =IFERROR(Historical_FS!C14,0) -> 0.26764086 | D11: =IFERROR(Historical_FS!D14,0) -> 0.26448268 | E11: =IFERROR(Historical_FS!E14,0) -> 0.26000328 | F11: =IFERROR(Historical_FS!F14,0) -> 0.26743302 | G11: =IFERROR(Historical_FS!G14,0) -> 0.23341342 | H11: =IFERROR(Historical_FS!H14,0) -> 0.24063336 | I11: =IFERROR(Historical_FS!I14,0) -> 0.24487985 | J11: =IFERROR(Historical_FS!J14,0) -> 0.22110641 | ... L11: =IFERROR(Historical_FS!L14,0) -> 0.19198712 | N11: =AVERAGE(C11:L11) -> 0.23999299 | O11: =MEDIAN(C11:L11) -> 0.2427566
B12: EBITDA Margin | C12: =IFERROR(Historical_FS!C20,0) -> 0.08776977 | D12: =IFERROR(Historical_FS!D20,0) -> 0.10199897 | E12: =IFERROR(Historical_FS!E20,0) -> 0.10080582 | F12: =IFERROR(Historical_FS!F20,0) -> 0.11699601 | G12: =IFERROR(Historical_FS!G20,0) -> 0.079698762 | H12: =IFERROR(Historical_FS!H20,0) -> 0.11611514 | I12: =IFERROR(Historical_FS!I20,0) -> 0.12032039 | J12: =IFERROR(Historical_FS!J20,0) -> 0.10359408 | ... L12: =IFERROR(Historical_FS!L20,0) -> 0.095416971 | N12: =AVERAGE(C12:L12) -> 0.10169001 | O12: =MEDIAN(C12:L12) -> 0.1014024
B13: EBIT Margin | C13: =IFERROR((Historical_FS!C19-Historical_FS!C25)/Historical_FS!C7,0) -> 0.079434696 | D13: =IFERROR((Historical_FS!D19-Historical_FS!D25)/Historical_FS!D7,0) -> 0.093845632 | E13: =IFERROR((Historical_FS!E19-Historical_FS!E25)/Historical_FS!E7,0) -> 0.09257265 | F13: =IFERROR((Historical_FS!F19-Historical_FS!F25)/Historical_FS!F7,0) -> 0.10046551 | G13: =IFERROR((Historical_FS!G19-Historical_FS!G25)/Historical_FS!G7,0) -> 0.062372944 | H13: =IFERROR((Historical_FS!H19-Historical_FS!H25)/Historical_FS!H7,0) -> 0.1022605 | I13: =IFERROR((Historical_FS!I19-Historical_FS!I25)/Historical_FS!I7,0) -> 0.10945163 | J13: =IFERROR((Historical_FS!J19-Historical_FS!J25)/Historical_FS!J7,0) -> 0.092161929 | ... L13: =IFERROR((Historical_FS!L19-Historical_FS!L25)/Historical_FS!L7,0) -> 0.085986025 | N13: =AVERAGE(C13:L13) -> 0.090127284 | O13: =MEDIAN(C13:L13) -> 0.092367289
B14: EBT Margin | C14: =IFERROR(Historical_FS!C29,0) -> 0.073392842 | D14: =IFERROR(Historical_FS!D29,0) -> 0.094900858 | E14: =IFERROR(Historical_FS!E29,0) -> 0.098940163 | F14: =IFERROR(Historical_FS!F29,0) -> 0.099847995 | G14: =IFERROR(Historical_FS!G29,0) -> 0.061310294 | H14: =IFERROR(Historical_FS!H29,0) -> 0.10083683 | I14: =IFERROR(Historical_FS!I29,0) -> 0.10959951 | J14: =IFERROR(Historical_FS!J29,0) -> 0.090498003 | ... L14: =IFERROR(Historical_FS!L29,0) -> 0.077651169 | N14: =AVERAGE(C14:L14) -> 0.08819909 | O14: =MEDIAN(C14:L14) -> 0.092699431
B15: Net Profit Margin | C15: =IFERROR(Historical_FS!C35,0) -> 0.052581927 | D15: =IFERROR(Historical_FS!D35,0) -> 0.068357675 | E15: =IFERROR(Historical_FS!E35,0) -> 0.070210006 | F15: =IFERROR(Historical_FS!F35,0) -> 0.070919628 | G15: =IFERROR(Historical_FS!G35,0) -> 0.045000924 | H15: =IFERROR(Historical_FS!H35,0) -> 0.076322095 | I15: =IFERROR(Historical_FS!I35,0) -> 0.08069008 | J15: =IFERROR(Historical_FS!J35,0) -> 0.068436301 | ... L15: =IFERROR(Historical_FS!L35,0) -> 0.057921538 | N15: =AVERAGE(C15:L15) -> 0.064563734 | O15: =MEDIAN(C15:L15) -> 0.068396988
B17: SalesExpenses%Sales | C17: =IFERROR(Historical_FS!C17,0) -> 0.17987109 | D17: =IFERROR(Historical_FS!D17,0) -> 0.16248371 | E17: =IFERROR(Historical_FS!E17,0) -> 0.15919745 | F17: =IFERROR(Historical_FS!F17,0) -> 0.15043701 | G17: =IFERROR(Historical_FS!G17,0) -> 0.15371466 | H17: =IFERROR(Historical_FS!H17,0) -> 0.12451821 | I17: =IFERROR(Historical_FS!I17,0) -> 0.12455946 | J17: =IFERROR(Historical_FS!J17,0) -> 0.11751233 | ... L17: =IFERROR(Historical_FS!L17,0) -> 0.09657015 | N17: =AVERAGE(C17:L17) -> 0.13830297 | O17: =MEDIAN(C17:L17) -> 0.13749824
B18: Depreciation%Sales | C18: =IFERROR(Historical_FS!C25/Historical_FS!C7,0) -> 0.008335074 | D18: =IFERROR(Historical_FS!D25/Historical_FS!D7,0) -> 0.0081533421 | E18: =IFERROR(Historical_FS!E25/Historical_FS!E7,0) -> 0.0082331742 | F18: =IFERROR(Historical_FS!F25/Historical_FS!F7,0) -> 0.016530496 | G18: =IFERROR(Historical_FS!G25/Historical_FS!G7,0) -> 0.017325818 | H18: =IFERROR(Historical_FS!H25/Historical_FS!H7,0) -> 0.013854648 | I18: =IFERROR(Historical_FS!I25/Historical_FS!I7,0) -> 0.010868762 | J18: =IFERROR(Historical_FS!J25/Historical_FS!J7,0) -> 0.011432151 | ... L18: =IFERROR(Historical_FS!L25/Historical_FS!L7,0) -> 0.0094309463 | N18: =AVERAGE(C18:L18) -> 0.011562729 | O18: =MEDIAN(C18:L18) -> 0.011150456
B19: OperatingIncome%Sales | C19: =C13 -> 0.079434696 | D19: =D13 -> 0.093845632 | E19: =E13 -> 0.09257265 | F19: =F13 -> 0.10046551 | G19: =G13 -> 0.062372944 | H19: =H13 -> 0.1022605 | I19: =I13 -> 0.10945163 | J19: =J13 -> 0.092161929 | ... L19: =L13 -> 0.085986025 | N19: =AVERAGE(C19:L19) -> 0.090127284 | O19: =MEDIAN(C19:L19) -> 0.092367289
B21: Return on Capital Employed | C21: =IFERROR((Historical_FS!C19-Historical_FS!C26)/(Historical_FS!C49+Historical_FS!C50+Historical_FS!C51),0) -> 0.19033979 | D21: =IFERROR((Historical_FS!D19-Historical_FS!D26)/(Historical_FS!D49+Historical_FS!D50+Historical_FS!D51),0) -> 0.24247434 | E21: =IFERROR((Historical_FS!E19-Historical_FS!E26)/(Historical_FS!E49+Historical_FS!E50+Historical_FS!E51),0) -> 0.23558444 | F21: =IFERROR((Historical_FS!F19-Historical_FS!F26)/(Historical_FS!F49+Historical_FS!F50+Historical_FS!F51),0) -> 0.24073731 | G21: =IFERROR((Historical_FS!G19-Historical_FS!G26)/(Historical_FS!G49+Historical_FS!G50+Historical_FS!G51),0) -> 0.13132719 | H21: =IFERROR((Historical_FS!H19-Historical_FS!H26)/(Historical_FS!H49+Historical_FS!H50+Historical_FS!H51),0) -> 0.20171228 | I21: =IFERROR((Historical_FS!I19-Historical_FS!I26)/(Historical_FS!I49+Historical_FS!I50+Historical_FS!I51),0) -> 0.23008715 | J21: =IFERROR((Historical_FS!J19-Historical_FS!J26)/(Historical_FS!J49+Historical_FS!J50+Historical_FS!J51),0) -> 0.21235057 | ... L21: =IFERROR((Historical_FS!L19-Historical_FS!L26)/(Historical_FS!L49+Historical_FS!L50+Historical_FS!L51),0) -> 0.18040304 | N21: =AVERAGE(C21:L21) -> 0.20407511 | O21: =MEDIAN(C21:L21) -> 0.20703142
B22: Retained Earnings% | C22: =Historical_FS!C45 -> 0.66895652 | D22: =Historical_FS!D45 -> 0.69787006 | E22: =Historical_FS!E45 -> 0.68033702 | F22: =Historical_FS!F45 -> 0.76155392 | G22: =Historical_FS!G45 -> 0.63449692 | H22: =Historical_FS!H45 -> 0.69631483 | I22: =Historical_FS!I45 -> 0.72816127 | J22: =Historical_FS!J45 -> 0.71996568 | ... L22: =Historical_FS!L45 -> 0.73684211 | N22: =AVERAGE(C22:L22) -> 0.7031121 | O22: =MEDIAN(C22:L22) -> 0.70224639
B23: Return on Equity | C23: =IFERROR(Historical_FS!C34/SUM(Historical_FS!C49:C50),0) -> 0.16474891 | D23: =IFERROR(Historical_FS!D34/SUM(Historical_FS!D49:D50),0) -> 0.21649037 | E23: =IFERROR(Historical_FS!E34/SUM(Historical_FS!E49:E50),0) -> 0.228767 | F23: =IFERROR(Historical_FS!F34/SUM(Historical_FS!F49:F50),0) -> 0.22387164 | G23: =IFERROR(Historical_FS!G34/SUM(Historical_FS!G49:G50),0) -> 0.12991863 | H23: =IFERROR(Historical_FS!H34/SUM(Historical_FS!H49:H50),0) -> 0.23626787 | I23: =IFERROR(Historical_FS!I34/SUM(Historical_FS!I49:I50),0) -> 0.27626361 | J23: =IFERROR(Historical_FS!J34/SUM(Historical_FS!J49:J50),0) -> 0.37219206 | ... L23: =IFERROR(Historical_FS!L34/SUM(Historical_FS!L49:L50),0) -> 0.32305929 | N23: =AVERAGE(C23:L23) -> 0.24586578 | O23: =MEDIAN(C23:L23) -> 0.23251743
B24: Self Sustained Growth Rate | C24: =IFERROR(C22*C23,0) -> 0.11020986 | D24: =IFERROR(D22*D23,0) -> 0.15108215 | E24: =IFERROR(E22*E23,0) -> 0.15563866 | F24: =IFERROR(F22*F23,0) -> 0.17049033 | G24: =IFERROR(G22*G23,0) -> 0.082432973 | H24: =IFERROR(H22*H23,0) -> 0.16451682 | I24: =IFERROR(I22*I23,0) -> 0.20116446 | J24: =IFERROR(J22*J23,0) -> 0.26796551 | ... L24: =IFERROR(L22*L23,0) -> 0.23804369 | N24: =AVERAGE(C24:L24) -> 0.17444006 | O24: =MEDIAN(C24:L24) -> 0.16750358
B25: Interest Coverage Ratio | C25: =IFERROR((Historical_FS!C19-Historical_FS!C25)/Historical_FS!C22,0) -> 27.911235 | D25: =IFERROR((Historical_FS!D19-Historical_FS!D25)/Historical_FS!D22,0) -> 28.585979 | E25: =IFERROR((Historical_FS!E19-Historical_FS!E25)/Historical_FS!E22,0) -> 34.848687 | F25: =IFERROR((Historical_FS!F19-Historical_FS!F25)/Historical_FS!F22,0) -> 12.740964 | G25: =IFERROR((Historical_FS!G19-Historical_FS!G25)/Historical_FS!G22,0) -> 6.6502463 | H25: =IFERROR((Historical_FS!H19-Historical_FS!H25)/Historical_FS!H22,0) -> 13.509174 | I25: =IFERROR((Historical_FS!I19-Historical_FS!I25)/Historical_FS!I22,0) -> 14.803333 | J25: =IFERROR((Historical_FS!J19-Historical_FS!J25)/Historical_FS!J22,0) -> 7.6058158 | ... L25: =IFERROR((Historical_FS!L19-Historical_FS!L25)/Historical_FS!L22,0) -> 6.3822034 | N25: =AVERAGE(C25:L25) -> 15.828528 | O25: =MEDIAN(C25:L25) -> 13.125069
B27: Debtor Turnover Ratio | C27: =IFERROR(Historical_FS!C7/Historical_FS!C61,0) -> 63.87683 | D27: =IFERROR(Historical_FS!D7/Historical_FS!D61,0) -> 54.515777 | E27: =IFERROR(Historical_FS!E7/Historical_FS!E61,0) -> 47.041313 | F27: =IFERROR(Historical_FS!F7/Historical_FS!F61,0) -> 67.474359 | G27: =IFERROR(Historical_FS!G7/Historical_FS!G61,0) -> 59.136612 | H27: =IFERROR(Historical_FS!H7/Historical_FS!H61,0) -> 50.971681 | I27: =IFERROR(Historical_FS!I7/Historical_FS!I61,0) -> 60.200297 | J27: =IFERROR(Historical_FS!J7/Historical_FS!J61,0) -> 50.180747 | ... L27: =IFERROR(Historical_FS!L7/Historical_FS!L61,0) -> 95.615721 | N27: =AVERAGE(C27:L27) -> 60.562008 | O27: =MEDIAN(C27:L27) -> 57.871677
B28: Creditor Turnover Ratio | C28: =IFERROR(Historical_FS!C7/Historical_FS!C52,0) -> 5.7837846 | D28: =IFERROR(Historical_FS!D7/Historical_FS!D52,0) -> 5.8828057 | E28: =IFERROR(Historical_FS!E7/Historical_FS!E52,0) -> 6.0918653 | F28: =IFERROR(Historical_FS!F7/Historical_FS!F52,0) -> 6.3543616 | G28: =IFERROR(Historical_FS!G7/Historical_FS!G52,0) -> 6.5409489 | H28: =IFERROR(Historical_FS!H7/Historical_FS!H52,0) -> 6.2470716 | I28: =IFERROR(Historical_FS!I7/Historical_FS!I52,0) -> 6.9932782 | J28: =IFERROR(Historical_FS!J7/Historical_FS!J52,0) -> 7.7096287 | ... L28: =IFERROR(Historical_FS!L7/Historical_FS!L52,0) -> 6.1518578 | N28: =AVERAGE(C28:L28) -> 6.5088936 | O28: =MEDIAN(C28:L28) -> 6.3007166
B29: Inventory Turnover | C29: =IFERROR(Historical_FS!C7/Historical_FS!C62,0) -> 2.6921498 | D29: =IFERROR(Historical_FS!D7/Historical_FS!D62,0) -> 2.7207098 | E29: =IFERROR(Historical_FS!E7/Historical_FS!E62,0) -> 2.8099198 | F29: =IFERROR(Historical_FS!F7/Historical_FS!F62,0) -> 2.5980501 | G29: =IFERROR(Historical_FS!G7/Historical_FS!G62,0) -> 2.574215 | H29: =IFERROR(Historical_FS!H7/Historical_FS!H62,0) -> 2.1161731 | I29: =IFERROR(Historical_FS!I7/Historical_FS!I62,0) -> 2.4466353 | J29: =IFERROR(Historical_FS!J7/Historical_FS!J62,0) -> 2.681434 | ... L29: =IFERROR(Historical_FS!L7/Historical_FS!L62,0) -> 2.0490841 | N29: =AVERAGE(C29:L29) -> 2.4833418 | O29: =MEDIAN(C29:L29) -> 2.5861326
B30: Fixed Asset Turnover | C30: =IFERROR(Historical_FS!C7/Historical_FS!C55,0) -> 11.155554 | D30: =IFERROR(Historical_FS!D7/Historical_FS!D55,0) -> 10.937482 | E30: =IFERROR(Historical_FS!E7/Historical_FS!E55,0) -> 12.624883 | F30: =IFERROR(Historical_FS!F7/Historical_FS!F55,0) -> 7.9954425 | G30: =IFERROR(Historical_FS!G7/Historical_FS!G55,0) -> 8.5786762 | H30: =IFERROR(Historical_FS!H7/Historical_FS!H55,0) -> 11.320362 | I30: =IFERROR(Historical_FS!I7/Historical_FS!I55,0) -> 13.534023 | J30: =IFERROR(Historical_FS!J7/Historical_FS!J55,0) -> 13.772985 | ... L30: =IFERROR(Historical_FS!L7/Historical_FS!L55,0) -> 12.733934 | N30: =AVERAGE(C30:L30) -> 11.753665 | O30: =MEDIAN(C30:L30) -> 11.972622
B31: Capital Turnover Ratio | C31: =IFERROR(Historical_FS!C7/SUM(Historical_FS!C49:C50),0) -> 3.1331851 | D31: =IFERROR(Historical_FS!D7/SUM(Historical_FS!D49:D50),0) -> 3.1670236 | E31: =IFERROR(Historical_FS!E7/SUM(Historical_FS!E49:E50),0) -> 3.2583248 | F31: =IFERROR(Historical_FS!F7/SUM(Historical_FS!F49:F50),0) -> 3.1566952 | G31: =IFERROR(Historical_FS!G7/SUM(Historical_FS!G49:G50),0) -> 2.8870215 | H31: =IFERROR(Historical_FS!H7/SUM(Historical_FS!H49:H50),0) -> 3.0956681 | I31: =IFERROR(Historical_FS!I7/SUM(Historical_FS!I49:I50),0) -> 3.4237617 | J31: =IFERROR(Historical_FS!J7/SUM(Historical_FS!J49:J50),0) -> 5.438518 | ... L31: =IFERROR(Historical_FS!L7/SUM(Historical_FS!L49:L50),0) -> 5.577533 | N31: =AVERAGE(C31:L31) -> 3.8338694 | O31: =MEDIAN(C31:L31) -> 3.2126742
B33: (In Days)
B34: Debtor Days | C34: =IFERROR(365/C27,0) -> 5.714122 | D34: =IFERROR(365/D27,0) -> 6.6953095 | E34: =IFERROR(365/E27,0) -> 7.7591372 | F34: =IFERROR(365/F27,0) -> 5.4094623 | G34: =IFERROR(365/G27,0) -> 6.1721493 | H34: =IFERROR(365/H27,0) -> 7.1608389 | I34: =IFERROR(365/I27,0) -> 6.063093 | J34: =IFERROR(365/J27,0) -> 7.2737061 | ... L34: =IFERROR(365/L27,0) -> 3.8173639 | N34: =AVERAGE(C34:L34) -> 6.2513177 | O34: =MEDIAN(C34:L34) -> 6.3100723
B35: Payable Days | C35: =IFERROR(365/C28,0) -> 63.107468 | D35: =IFERROR(365/D28,0) -> 62.045225 | E35: =IFERROR(365/E28,0) -> 59.915967 | F35: =IFERROR(365/F28,0) -> 57.440861 | G35: =IFERROR(365/G28,0) -> 55.802301 | H35: =IFERROR(365/H28,0) -> 58.427376 | I35: =IFERROR(365/I28,0) -> 52.192976 | J35: =IFERROR(365/J28,0) -> 47.343395 | ... L35: =IFERROR(365/L28,0) -> 59.33167 | N35: =AVERAGE(C35:L35) -> 56.537997 | O35: =MEDIAN(C35:L35) -> 57.934118
B36: Inventory Days | C36: =IFERROR(365/C29,0) -> 135.57938 | D36: =IFERROR(365/D29,0) -> 134.15617 | E36: =IFERROR(365/E29,0) -> 129.89694 | F36: =IFERROR(365/F29,0) -> 140.48998 | G36: =IFERROR(365/G29,0) -> 141.7908 | H36: =IFERROR(365/H29,0) -> 172.48116 | I36: =IFERROR(365/I29,0) -> 149.18447 | J36: =IFERROR(365/J29,0) -> 136.12119 | ... L36: =IFERROR(365/L29,0) -> 178.12837 | N36: =AVERAGE(C36:L36) -> 148.79879 | O36: =MEDIAN(C36:L36) -> 141.14039
B37: Cash Conversion Cycle | C37: =SUM(C34,C36)-C35 -> 78.186034 | D37: =SUM(D34,D36)-D35 -> 78.806255 | E37: =SUM(E34,E36)-E35 -> 77.740114 | F37: =SUM(F34,F36)-F35 -> 88.458579 | G37: =SUM(G34,G36)-G35 -> 92.160645 | H37: =SUM(H34,H36)-H35 -> 121.21463 | I37: =SUM(I34,I36)-I35 -> 103.05459 | J37: =SUM(J34,J36)-J35 -> 96.051503 | ... L37: =SUM(L34,L36)-L35 -> 122.61406 | N37: =AVERAGE(C37:L37) -> 98.512113 | O37: =MEDIAN(C37:L37) -> 94.106074
B39: CFO/Sales | C39: =IFERROR(Historical_FS!C82/Historical_FS!C7,0) -> 0.19817764 | D39: =IFERROR(Historical_FS!D82/Historical_FS!D7,0) -> -0.079839849 | E39: =IFERROR(Historical_FS!E82/Historical_FS!E7,0) -> 0.047475746 | F39: =IFERROR(Historical_FS!F82/Historical_FS!F7,0) -> -0.12445373 | G39: =IFERROR(Historical_FS!G82/Historical_FS!G7,0) -> 0.31232674 | H39: =IFERROR(Historical_FS!H82/Historical_FS!H7,0) -> -0.1369492 | I39: =IFERROR(Historical_FS!I82/Historical_FS!I7,0) -> -0.025705484 | J39: =IFERROR(Historical_FS!J82/Historical_FS!J7,0) -> -0.01646308 | ... L39: =IFERROR(Historical_FS!L82/Historical_FS!L7,0) -> 0.051036719 | N39: =AVERAGE(C39:L39) -> 0.013021381 | O39: =MEDIAN(C39:L39) -> -0.021084282
B40: CFO/Total Assets | C40: =IFERROR(Historical_FS!C82/Historical_FS!C66,0) -> 0.31257545 | D40: =IFERROR(Historical_FS!D82/Historical_FS!D66,0) -> -0.13517431 | E40: =IFERROR(Historical_FS!E82/Historical_FS!E66,0) -> 0.080188969 | F40: =IFERROR(Historical_FS!F82/Historical_FS!F66,0) -> -0.19344359 | G40: =IFERROR(Historical_FS!G82/Historical_FS!G66,0) -> 0.41109219 | H40: =IFERROR(Historical_FS!H82/Historical_FS!H66,0) -> -0.1861431 | I40: =IFERROR(Historical_FS!I82/Historical_FS!I66,0) -> -0.038601036 | J40: =IFERROR(Historical_FS!J82/Historical_FS!J66,0) -> -0.026658636 | ... L40: =IFERROR(Historical_FS!L82/Historical_FS!L66,0) -> 0.073809878 | N40: =AVERAGE(C40:L40) -> 0.015575875 | O40: =MEDIAN(C40:L40) -> -0.032629836
B41: CFO/Total Debt | C41: =IFERROR(Historical_FS!C82/Historical_FS!C51,0) -> 1.3960678 | D41: =IFERROR(Historical_FS!D82/Historical_FS!D51,0) -> -0.76108361 | E41: =IFERROR(Historical_FS!E82/Historical_FS!E51,0) -> 0.39239776 | F41: =IFERROR(Historical_FS!F82/Historical_FS!F51,0) -> -0.73554183 | G41: =IFERROR(Historical_FS!G82/Historical_FS!G51,0) -> 1.1990067 | H41: =IFERROR(Historical_FS!H82/Historical_FS!H51,0) -> -0.54213058 | I41: =IFERROR(Historical_FS!I82/Historical_FS!I51,0) -> -0.11134835 | J41: =IFERROR(Historical_FS!J82/Historical_FS!J51,0) -> -0.054160227 | ... L41: =IFERROR(Historical_FS!L82/Historical_FS!L51,0) -> 0.14597825 | N41: =AVERAGE(C41:L41) -> 0.065161946 | O41: =MEDIAN(C41:L41) -> -0.082754289

Sheet Data Sheet
A1: COMPANY NAME | B1: TITAN COMPANY LTD | E1: =IF(B2<>B3, "A NEW VERSION OF THE WORKSHEET IS AVAILABLE", "")
A2: LATEST VERSION | B2: 2.1 | E2: PLEASE DO NOT MAKE ANY CHANGES TO THIS SHEET
A3: CURRENT VERSION | B3: 2.1
A5: META
A6: Number of shares | B6: =IF(B9>0, B9/B8, 0) -> 88.778617
A7: Face Value | B7: 1
A8: Current Price | B8: 4515.7
A9: Market Capitalization | B9: 400897.6
A15: PROFIT & LOSS
A16: Report Date | B16: 42825 | C16: 43190 | D16: 43555 | E16: 43921 | F16: 44286 | G16: 44651 | H16: 45016 | I16: 45382 | J16: 45747 | K16: 46112
A17: Sales | B17: 13260.83 | C17: 16119.77 | D17: 19778.52 | E17: 21052 | F17: 21644 | G17: 28799 | H17: 40575 | I17: 51084 | J17: 60456 | K17: 87584
A18: Raw Material Cost | B18: 9821.14 | C18: 12664.83 | D18: 15170.66 | E18: 16033 | F18: 16292 | G18: 26436 | H18: 32589 | I18: 42103 | J18: 55271 | K18: 80243
A19: Change in Inventory | B19: 313.71 | C19: 978.61 | D19: 776.41 | E19: 878 | F19: -122 | G19: 4795 | H19: 2234 | I19: 2671 | J19: 7815 | K19: 9936
A20: Power and Fuel | B20: 43.84 | C20: 45.32 | D20: 48.51 | E20: 52 | F20: 37 | G20: 45 | H20: 59 | I20: 71 | J20: 78 | K20: 87
A21: Other Mfr. Exp | B21: 160.42 | C21: 124.83 | D21: 193.28 | E21: 215 | F21: 141 | G21: 183 | H21: 225 | I21: 286 | J21: 326 | K21: 375
A22: Employee Cost | B22: 894.32 | C22: 906.26 | D22: 1024.44 | E22: 1204 | F22: 1069 | G22: 1356 | H22: 1656 | I22: 1875 | J22: 2164 | K22: 2692
A23: Selling and admin | B23: 1211.16 | C23: 1277.81 | D23: 1454.32 | E23: 1470 | F23: 1029 | G23: 1697 | H23: 2715 | I23: 3249 | J23: 3494 | K23: 4185
A24: Other Expenses | B24: 279.76 | C24: 435.13 | D24: 669.93 | E24: 493 | F24: 1229 | G24: 533 | H24: 683 | I24: 879 | J24: 1244 | K24: 1581
A25: Other Income | B25: -42.38 | C25: 69.93 | D25: 178.48 | E25: 153 | F25: 180 | G25: 177 | H25: 306 | I25: 534 | J25: 487 | K25: 450
A26: Depreciation | B26: 110.53 | C26: 131.43 | D26: 162.84 | E26: 348 | F26: 375 | G26: 399 | H26: 441 | I26: 584 | J26: 693 | K26: 826
A27: Interest | B27: 37.74 | C27: 52.92 | D27: 52.54 | E27: 166 | F27: 203 | G27: 218 | H27: 300 | I27: 619 | J27: 953 | K27: 1180
... A31: Dividend Amount | B31: 230.83 | C31: 332.92 | D31: 443.9 | E31: 356 | F31: 356 | G31: 667.5 | H31: 890 | I31: 979 | J31: 979 | K31: 1335
A40: Quarters
A41: Report Date | B41: 45382 | C41: 45473 | D41: 45565 | E41: 45657 | F41: 45747 | G41: 45838 | H41: 45930 | I41: 46022 | J41: 46112 | K41: 46203
A42: Sales | B42: 12494 | C42: 13266 | D42: 14534 | E42: 17740 | F42: 14916 | G42: 16523 | H42: 18725 | I42: 25416 | J42: 26920 | K42: 21356
A43: Expenses | B43: 11303 | C43: 12019 | D43: 13298 | E43: 16066 | F43: 13379 | G43: 14693 | H43: 16850 | I43: 22703 | J43: 24982 | K43: 18466
A44: Other Income | B44: 159 | C44: 120 | D44: 123 | E44: 128 | F44: 116 | G44: 105 | H44: 113 | I44: -1 | J44: 235 | K44: 148
A45: Depreciation | B45: 158 | C45: 164 | D45: 171 | E45: 175 | F45: 183 | G45: 184 | H45: 189 | I45: 207 | J45: 246 | K45: 256
A46: Interest | B46: 201 | C46: 230 | D46: 240 | E46: 231 | F46: 252 | G46: 271 | H46: 277 | I46: 282 | J46: 350 | K46: 353
A47: Profit before tax | B47: 991 | C47: 973 | D47: 948 | E47: 1396 | F47: 1218 | G47: 1480 | H47: 1522 | I47: 2223 | J47: 1577 | K47: 2429
A48: Tax | B48: 220 | C48: 258 | D48: 244 | E48: 349 | F48: 347 | G48: 389 | H48: 402 | I48: 539 | J48: 398 | K48: 652
A49: Net profit | B49: 771 | C49: 715 | D49: 704 | E49: 1047 | F49: 871 | G49: 1091 | H49: 1120 | I49: 1684 | J49: 1179 | K49: 1777
A50: Operating Profit | B50: 1191 | C50: 1247 | D50: 1236 | E50: 1674 | F50: 1537 | G50: 1830 | H50: 1875 | I50: 2713 | J50: 1938 | K50: 2890
A55: BALANCE SHEET
A56: Report Date | B56: 42825 | C56: 43190 | D56: 43555 | E56: 43921 | F56: 44286 | G56: 44651 | H56: 45016 | I56: 45382 | J56: 45747 | K56: 46112
A57: Equity Share Capital | B57: 88.78 | C57: 88.78 | D57: 88.78 | E57: 89 | F57: 89 | G57: 89 | H57: 89 | I57: 89 | J57: 89 | K57: 89
A58: Reserves | B58: 4143.6 | C58: 5001.1 | D58: 5981.37 | E58: 6580 | F58: 7408 | G58: 9214 | H58: 11762 | I58: 9304 | J58: 11535 | K58: 15614
A59: Borrowings | B59: 1882.43 | C59: 1691.01 | D59: 2392.98 | E59: 3562 | F59: 5638 | G59: 7275 | H59: 9367 | I59: 15528 | J59: 20777 | K59: 30621
A60: Other Liabilities | B60: 2292.76 | C60: 2740.15 | D60: 3246.71 | E60: 3313 | F60: 3309 | G60: 4610 | H60: 5802 | I60: 6626 | J60: 8244 | K60: 14237
A61: Total | B61: 8407.57 | C61: 9521.04 | D61: 11709.84 | E61: 13544 | F61: 16444 | G61: 21188 | H61: 27020 | I61: 31547 | J61: 40645 | K61: 60561
...

Sheet Forecasting
B2: ="Forecasting:" & 'Data Sheet'!B1 -> Forecasting:TITAN COMPANY LTD
B4: Forecasting: Sales | G4: Forecasting: EBITDA | L4: Forecasting: EPS
B5: Year Weight | C5: Year | D5: Sales | E5: Sales Growth | G5: Year Weight | H5: Year | I5: EBITDA | J5: EBIDTA Growth | L5: Year Weight | M5: Year | N5: EPS | O5: EPS Growth
B6: 1 | C6: ='Data Sheet'!B16 -> 42825 | D6: {=TRANSPOSE('Data Sheet'!B17:K17)} -> 13260.83 | E6: - | G6: 1 | H6: ='Data Sheet'!B16 -> 42825 | I6: {=TRANSPOSE(Historical_FS!C19:L19)} -> 1163.9 | J6: - | L6: 1 | M6: ='Data Sheet'!B16 -> 42825 | N6: {=TRANSPOSE(Historical_FS!C39:L39)} -> 7.8540212 | O6: -
B7: 2 | C7: =C6+365 -> 43190 | D7: 16119.77 | E7: =D7/D6-1 -> 0.21559284 | G7: 2 | H7: =H6+365 -> 43190 | I7: 1644.2 | J7: =I7/I6-1 -> 0.41266432 | L7: 2 | M7: =M6+365 -> 43190 | N7: 12.411692 | O7: =N7/N6-1 -> 0.58029773
B8: 3 | C8: =C7+365 -> 43555 | D8: 19778.52 | E8: =D8/D7-1 -> 0.22697284 | G8: 3 | H8: =H7+365 -> 43555 | I8: 1993.79 | J8: =I8/I7-1 -> 0.21262012 | L8: 3 | M8: =M7+365 -> 43555 | N8: 15.641473 | O8: =N8/N7-1 -> 0.26022089
B9: 4 | C9: =C8+365 -> 43920 | D9: 21052 | E9: =D9/D8-1 -> 0.064387022 | G9: 4 | H9: =H8+365 -> 43920 | I9: 2463 | J9: =I9/I8-1 -> 0.23533572 | L9: 4 | M9: =M8+365 -> 43920 | N9: 16.816851 | O9: =N9/N8-1 -> 0.075144925
B10: 5 | C10: =C9+365 -> 44285 | D10: 21644 | E10: =D10/D9-1 -> 0.028120844 | G10: 5 | H10: =H9+365 -> 44285 | I10: 1725 | J10: =I10/I9-1 -> -0.29963459 | L10: 5 | M10: =M9+365 -> 44285 | N10: 10.970939 | O10: =N10/N9-1 -> -0.34762224
B11: 6 | C11: =C10+365 -> 44650 | D11: 28799 | E11: =D11/D10-1 -> 0.3305766 | G11: 6 | H11: =H10+365 -> 44650 | I11: 3344 | J11: =I11/I10-1 -> 0.93855072 | L11: 6 | M11: =M10+365 -> 44650 | N11: 24.757828 | O11: =N11/N10-1 -> 1.2566735
B12: 7 | C12: =C11+365 -> 45015 | D12: 40575 | E12: =D12/D11-1 -> 0.40890309 | G12: 7 | H12: =H11+365 -> 45015 | I12: 4882 | J12: =I12/I11-1 -> 0.45992823 | L12: 7 | M12: =M11+365 -> 45015 | N12: 36.877675 | O12: =N12/N11-1 -> 0.48953594
B13: 8 | C13: =C12+365 -> 45380 | D13: 51084 | E13: =D13/D12-1 -> 0.25900185 | G13: 8 | H13: =H12+365 -> 45380 | I13: 5292 | J13: =I13/I12-1 -> 0.083981975 | L13: 8 | M13: =M12+365 -> 45380 | N13: 39.378238 | O13: =N13/N12-1 -> 0.067806964
B14: 9 | C14: =C13+365 -> 45745 | D14: 60456 | E14: =D14/D13-1 -> 0.18346253 | G14: 9 | H14: =H13+365 -> 45745 | I14: 5694 | J14: =I14/I13-1 -> 0.075963719 | L14: 9 | M14: =M13+365 -> 45745 | N14: 37.587294 | O14: =N14/N13-1 -> -0.045480549
B15: 10 | C15: =C14+365 -> 46110 | D15: 87584 | E15: =D15/D14-1 -> 0.44872304 | G15: 10 | H15: =H14+365 -> 46110 | I15: 8357 | J15: =I15/I14-1 -> 0.46768528 | L15: 10 | M15: =M14+365 -> 46110 | N15: 57.141248 | O15: =N15/N14-1 -> 0.52022775
B16: 11 | C16: =C15+365 -> 46475 | D16: =FORECAST(B16,$D$6:$D$15,$B$6:$B$15) -> 76085.763 | E16: =D16/D15-1 -> -0.13128239 | G16: 11 | H16: =H15+365 -> 46475 | I16: =FORECAST(G16,$I$6:$I$15,$G$6:$G$15) -> 7604.3407 | J16: =I16/I15-1 -> -0.09006334 | L16: 11 | M16: =M15+365 -> 46475 | N16: =FORECAST(L16,$N$6:$N$15,$L$6:$L$15) -> 53.025974 | O16: =N16/N15-1 -> -0.072019318
B17: 12 | C17: =C16+365 -> 46840 | D17: =FORECAST(B17,$D$6:$D$15,$B$6:$B$15) -> 83367.664 | E17: =D17/D16-1 -> 0.095706475 | G17: 12 | H17: =H16+365 -> 46840 | I17: =FORECAST(G17,$I$6:$I$15,$G$6:$G$15) -> 8322.241 | J17: =I17/I16-1 -> 0.094406647 | L17: 12 | M17: =M16+365 -> 46840 | N17: =FORECAST(L17,$N$6:$N$15,$L$6:$L$15) -> 57.950019 | O17: =N17/N16-1 -> 0.092861003
B18: 13 | C18: =C17+365 -> 47205 | D18: =FORECAST(B18,$D$6:$D$15,$B$6:$B$15) -> 90649.564 | E18: =D18/D17-1 -> 0.087346819 | G18: 13 | H18: =H17+365 -> 47205 | I18: =FORECAST(G18,$I$6:$I$15,$G$6:$G$15) -> 9040.1413 | J18: =I18/I17-1 -> 0.086262859 | L18: 13 | M18: =M17+365 -> 47205 | N18: =FORECAST(L18,$N$6:$N$15,$L$6:$L$15) -> 62.874065 | O18: =N18/N17-1 -> 0.084970552
B19: 14 | C19: =C18+365 -> 47570 | D19: =FORECAST(B19,$D$6:$D$15,$B$6:$B$15) -> 97931.464 | E19: =D19/D18-1 -> 0.080330229 | G19: 14 | H19: =H18+365 -> 47570 | I19: =FORECAST(G19,$I$6:$I$15,$G$6:$G$15) -> 9758.0416 | J19: =I19/I18-1 -> 0.079412509 | L19: 14 | M19: =M18+365 -> 47570 | N19: =FORECAST(L19,$N$6:$N$15,$L$6:$L$15) -> 67.79811 | O19: =N19/N18-1 -> 0.078315998
